<?xml version="1.0"?>

<robot xmlns:xacro="http://ros.org/wiki/xacro">

  <xacro:include filename="$(find warehouse_simulation)/urdf/pioneer3dx_wheel.xacro"/>

  <!-- Chassis description -->
  <link name="base_link">
  <!-- CHECK THESE VALUES. THEY MAY BE COMPLETELY WRONG. -->
  <inertial>
    <mass value="40.0"/>
    <origin xyz="-0.045 0 0.148"/>
    <inertia ixx="0.3338" ixy="0.0" ixz="0.0" iyy="0.4783" 
             iyz="0.0" izz="0.3338"/>
  </inertial>
  <!-- The base visual is fine. Just the inertial is questionable.-->
  <visual>
    <origin xyz="-0.045 0 0.148" rpy="0 0 0"/>
    <geometry name="pioneer_geom">
    <mesh filename="package://warehouse_simulation/meshes/chassis.stl"/>
    </geometry>
    <material name="ChassisBlack">
    <color rgba="0.038 0.038 0.038 1.0"/>
    </material>
  </visual>
  <collision>
    <origin xyz="-0.045 0 0.148" rpy="0 0 0"/>
    <geometry>
        <box size="0.4 0.28 0.17"/>
    </geometry>
  </collision>
  </link>
  <gazebo reference="base_link">
  <material value="Gazebo/Black"/>
  </gazebo>

  <link name="top_plate">
  <inertial>
    <mass value="0.01"/>  
    <origin xyz="0 0 0"/>
    <inertia ixx="1" ixy="0" ixz="0"
         iyy="1" iyz="0"
         izz="1"/>
  </inertial>
  <visual>
    <origin xyz="0 0 0" rpy="0 0 0"/>
    <geometry name="pioneer_geom">
    <mesh filename="package://warehouse_simulation/meshes/top.stl"/>
    </geometry>
    <material name="TopBlack">
    <color rgba="0.038 0.038 0.038 1.0"/>
    </material>
  </visual>
  </link>
  <gazebo reference="top_plate">
  <material value="Gazebo/Black"/>
  </gazebo>

  <joint name="base_top_joint" type="fixed">
  <origin xyz="-0.045 0 0.24" rpy="0 0 0"/>
  <dynamics damping="500.0" friction="10.0"/>
  <parent link="base_link"/>
  <child link="top_plate"/>
  </joint>
  
  <link name="link_torso_0">
  <inertial>
    <mass value="0.001"/>  
    <origin rpy="0 0 0" xyz="-0.08848415 0.00021367 0.00000046"/>
      <inertia ixx="0.01413496" ixy="0.00092982" ixz="-0.00000010" iyy="0.01005357"
               iyz="-0.00000008" izz="0.01892525"/>
  </inertial>
  <visual>
    <geometry>
    <mesh filename="package://warehouse_simulation/urdf/meshes/LINK_1.stl"/>
    </geometry>
  </visual>
  </link>
  <gazebo reference="link_torso_0">
  </gazebo>

  <joint name="torso_0" type="fixed">
  <origin xyz="0.0 0.0 0.2805" rpy="0 0 0"/>
  <axis xyz="1 0 0"/>
  <parent link="base_link"/>
  <child link="link_torso_0"/>
  <dynamics damping="50.0" friction="1.0"/>
  </joint>
  
  <link name="link_torso_1">
  <inertial>
    <mass value="0.001"/>  
    <origin rpy="0 0 0" xyz="0.00728955 -0.01728522 0.06911380"/>
    <inertia ixx="0.14862640" ixy="-0.00142621" ixz="-0.00951385" iyy="0.13854733"
             iyz="-0.00975351" izz="0.02912982"/>
  </inertial>
  <visual>
    <geometry>
    <mesh filename="package://warehouse_simulation/urdf/meshes/LINK_2.stl"/>
    </geometry>
  </visual>
  </link>
  <gazebo reference="link_torso_1">
  </gazebo>

  <joint name="torso_1" type="fixed">
  <origin xyz="0.0 0.0 0.0" rpy="0 0 0"/>
  <axis xyz="0 1 0"/>
  <parent link="link_torso_0"/>
  <child link="link_torso_1"/>
  <dynamics damping="50.0" friction="1.0"/>
  </joint>
  
  <link name="link_torso_2">
  <inertial>
    <mass value="0.001"/>  
    <origin rpy="0 0 0" xyz="0.00653835 -0.01769536 0.05636582"/>
    <inertia ixx="0.12162270" ixy="-0.00127910" ixz="-0.00831678" iyy="0.11589190"
             iyz="-0.00873271" izz="0.03094484"/>
  </inertial>
  <visual>
    <geometry>
    <mesh filename="package://warehouse_simulation/urdf/meshes/LINK_3.stl"/>
    </geometry>
  </visual>
  </link>
  <gazebo reference="link_torso_2">
  </gazebo>

  <joint name="torso_2" type="fixed">
  <origin xyz="0.0 0.0 0.350" rpy="0 0 0"/>
  <axis xyz="0 1 0"/>
  <parent link="link_torso_1"/>
  <child link="link_torso_2"/>
  <dynamics damping="50.0" friction="1.0"/>
  </joint>
  
  <link name="link_torso_3">
  <inertial>
    <mass value="0.0001"/>  
    <origin rpy="0 0 0" xyz="-0.00574156 -0.01725975 0.00005610"/>
    <inertia ixx="0.00849870" ixy="0.00040861" ixz="-0.00000263" iyy="0.00929513"
             iyz="-0.00001243" izz="0.00955442"/>
  </inertial>
  <visual>
    <geometry>
    <mesh filename="package://warehouse_simulation/urdf/meshes/LINK_4.stl"/>
    </geometry>
  </visual>
  </link>
  <gazebo reference="link_torso_3">
  </gazebo>

  <joint name="torso_3" type="fixed">
  <origin xyz="0.0 0.0 0.350" rpy="0 0 0"/>
  <axis xyz="0 1 0"/>
  <parent link="link_torso_2"/>
  <child link="link_torso_3"/>
  <dynamics damping="50.0" friction="1.0"/>
  </joint>
  
  <link name="link_torso_4">
  <inertial>
    <mass value="0.0001"/>  
    <origin rpy="0 0 0" xyz="-0.09097095 0.00005085 0.02601950"/>
    <inertia ixx="0.01545991" ixy="0.00001883" ixz="-0.00780349" iyy="0.02550888"
             iyz="0.00000715" izz="0.01952563"/>
  </inertial>
  <visual>
    <geometry>
    <mesh filename="package://warehouse_simulation/urdf/meshes/LINK_5.stl"/>
    </geometry>
  </visual>
  </link>
  <gazebo reference="link_torso_4">
  </gazebo>

  <joint name="torso_4" type="fixed">
  <origin xyz="0.0 0.0 0.0" rpy="0 0 0"/>
  <axis xyz="1 0 0"/>
  <parent link="link_torso_3"/>
  <child link="link_torso_4"/>
  <dynamics damping="50.0" friction="1.0"/>
  </joint>
  
  <link name="link_torso_5">
  <inertial>
    <mass value="0.0001"/>  
    <origin rpy="0 0 0" xyz="-0.01338376 0.00025621 -0.03272487"/>
    <inertia ixx="0.21375525" ixy="0.00051520" ixz="0.00880124" iyy="0.16562090"
             iyz="-0.00023995" izz="0.13308879"/>
  </inertial>
  <visual>
    <geometry>
    <mesh filename="package://warehouse_simulation/urdf/meshes/LINK_6.stl"/>
    </geometry>
  </visual>
  </link>
  <gazebo reference="link_torso_5">
  </gazebo>

  <joint name="torso_5" type="fixed">
  <origin xyz="0.0 0.0 0.309426548461" rpy="0 0 0"/>
  <axis xyz="0 0 1"/>
  <parent link="link_torso_4"/>
  <child link="link_torso_5"/>
  <dynamics damping="50.0" friction="1.0"/>
  </joint>
  
  <link name="link_right_arm_0">
  <inertial>
    <mass value="0.0001"/>  
    <origin rpy="0 0 0" xyz="-0.00316662 0.03437181 -0.00000030"/>
    <inertia ixx="0.00230621" ixy="0.00039024" ixz="-0.00000256" iyy="0.00426418"
             iyz="0.00000118" izz="0.00432156"/>
  </inertial>
  <visual>
    <geometry>
    <mesh filename="package://warehouse_simulation/urdf/meshes/LINK_7.stl"/>
    </geometry>
  </visual>
  </link>
  <gazebo reference="link_right_arm_0">
  </gazebo>

  <joint name="right_arm_0" type="fixed">
  <origin rpy="-0.349065850  0.0 0.0" xyz="0.0 -0.220 0.080073451539 "/>
  <axis xyz="0 1 0"/>
  <parent link="link_torso_5"/>
  <child link="link_right_arm_0"/>
  <dynamics damping="50.0" friction="1.0"/>
  </joint>
  
  <link name="link_right_arm_1">
  <inertial>
    <mass value="0.0001"/>  
    <origin rpy="0 0 0" xyz="-0.00307855 -0.00124741 -0.01294324"/>
    <inertia ixx="0.00388490" ixy="-0.00001477" ixz="0.00011465" iyy="0.00447034"
             iyz="-0.00010023" izz="0.00288341"/>
  </inertial>
  <visual>
    <geometry>
    <mesh filename="package://warehouse_simulation/urdf/meshes/LINK_8.stl"/>
    </geometry>
  </visual>
  </link>
  <gazebo reference="link_right_arm_1">
  </gazebo>

  <joint name="right_arm_1" type="fixed">
  <origin rpy="0.349065850 0.0 0.0" xyz="0.0 0.0 0.0"/>
  <axis xyz="1 0 0"/>
  <parent link="link_right_arm_0"/>
  <child link="link_right_arm_1"/>
  <dynamics damping="50.0" friction="1.0"/>
  </joint>
  
  <link name="link_right_arm_2">
  <inertial>
    <mass value="0.0001"/>  
    <origin rpy="0 0 0" xyz="0.00115434 -0.00196635 -0.16192524"/>
    <inertia ixx="0.00980269" ixy="0.00005871" ixz="0.00051888" iyy="0.00924560"
             iyz="-0.00045932" izz="0.00329867"/>
  </inertial>
  <visual>
    <geometry>
    <mesh filename="package://warehouse_simulation/urdf/meshes/LINK_9.stl"/>
    </geometry>
  </visual>
  </link>
  <gazebo reference="link_right_arm_2">
  </gazebo>

  <joint name="right_arm_2" type="fixed">
  <origin rpy="0.0 0.0 0.0" xyz="0.0 0.0 0.0"/>
  <axis xyz="0 0 1"/>
  <parent link="link_right_arm_1"/>
  <child link="link_right_arm_2"/>
  <dynamics damping="50.0" friction="1.0"/>
  </joint>
  
  <link name="link_right_arm_3">
  <inertial>
    <mass value="0.0001"/>  
    <origin rpy="0 0 0" xyz="-0.01603135 -0.00692891 -0.04549811"/>
    <inertia ixx="0.00822606" ixy="0.00027620" ixz="-0.00156570" iyy="0.00844870"
             iyz="0.00076157" izz="0.00236614"/>
  </inertial>
  <visual>
    <geometry>
    <mesh filename="package://warehouse_simulation/urdf/meshes/LINK_10.stl"/>
    </geometry>
  </visual>
  </link>
  <gazebo reference="link_right_arm_3">
  </gazebo>

  <joint name="right_arm_3" type="fixed">
  <origin rpy="0.0 0.0 0.0" xyz="0.031 0.0 -0.276"/>
  <axis xyz="0 1 0"/>
  <parent link="link_right_arm_2"/>
  <child link="link_right_arm_3"/>
  <dynamics damping="50.0" friction="1.0"/>
  </joint>
  
  <link name="link_right_arm_4">
  <inertial>
    <mass value="0.0001"/>  
    <origin rpy="0 0 0" xyz="-0.00000011 -0.02696036 0.06182110"/>
    <inertia ixx="0.00082466" ixy="0.0" ixz="0.0" iyy="0.00075398" 
             iyz="-0.00025338" izz="0.00039794"/>
  </inertial>
  <visual>
    <geometry>
    <mesh filename="package://warehouse_simulation/urdf/meshes/LINK_11.stl"/>
    </geometry>
  </visual>
  </link>
  <gazebo reference="link_right_arm_4">
  </gazebo>

  <joint name="right_arm_4" type="fixed">
  <origin rpy="0.0 0.0 0.0" xyz="-0.031 0.0 -0.256"/>
  <axis xyz="0 0 1"/>
  <parent link="link_right_arm_3"/>
  <child link="link_right_arm_4"/>
  <dynamics damping="50.0" friction="1.0"/>
  </joint>
  
  <link name="link_right_arm_5">
  <inertial>
    <mass value="0.0001"/>  
    <origin rpy="0 0 0" xyz="0.00318034 -0.00532264 -0.02809655"/>
    <inertia ixx="0.00256054" ixy="-0.00002344" ixz="-0.00001563" iyy="0.00257233"
             iyz="0.00021608" izz="0.00156092"/>
  </inertial>
  <visual>
    <geometry>
    <mesh filename="package://warehouse_simulation/urdf/meshes/LINK_12.stl"/>
    </geometry>
  </visual>
  </link>
  <gazebo reference="link_right_arm_5">
  </gazebo>

  <joint name="right_arm_5" type="fixed">
  <origin rpy="0.0 0.0 0.0" xyz="0.0 0.0 0.0"/>
  <axis xyz="0 1 0"/>
  <parent link="link_right_arm_4"/>
  <child link="link_right_arm_5"/>
  <dynamics damping="50.0" friction="1.0"/>
  </joint>
  
  <link name="link_right_arm_6">
  <inertial>
    <mass value="0.0001"/>  
    <origin rpy="0 0 0" xyz="0.00066810 -0.00031708 -0.09636043"/>
    <inertia ixx="0.00013511" ixy="-0.00000242" ixz="-0.00000102" iyy="0.00014453"
             iyz="0.00000094" izz="0.00025431"/>
  </inertial>
  <visual>
    <geometry>
    <mesh filename="package://warehouse_simulation/urdf/meshes/LINK_13.stl"/>
    </geometry>
  </visual>
  </link>
  <gazebo reference="link_right_arm_6">
  </gazebo>

  <joint name="right_arm_6" type="fixed">
  <origin rpy="0.0 0.0 0.0" xyz="0.0 0.0 0.0"/>
  <axis xyz="0 0 1"/>
  <parent link="link_right_arm_5"/>
  <child link="link_right_arm_6"/>
  <dynamics damping="50.0" friction="1.0"/>
  </joint>
  
  <link name="link_left_arm_0">
  <inertial>
    <mass value="0.0001"/>  
    <origin rpy="0 0 0" xyz="-0.00316662 -0.03437151 0.00000242"/>
    <inertia ixx="0.00230624" ixy="-0.00039022" ixz="0.00000269" iyy="0.00426418"
             iyz="0.00000108" izz="0.00432159"/>
  </inertial>
  <visual>
    <geometry>
    <mesh filename="package://warehouse_simulation/urdf/meshes/LINK_14.stl"/>
    </geometry>
  </visual>
  </link>
  <gazebo reference="link_left_arm_0">
  </gazebo>

  <joint name="left_arm_0" type="fixed">
  <origin rpy="0.349065850  0.0 0.0" xyz="0.0 0.220 0.080073452 "/>
  <axis xyz="0 1 0"/>
  <parent link="link_torso_5"/>
  <child link="link_left_arm_0"/>
  <dynamics damping="50.0" friction="1.0"/>
  </joint>
  
  <link name="link_left_arm_1">
  <inertial>
    <mass value="0.0001"/>  
    <origin rpy="0 0 0" xyz="-0.00183470 0.00040596 -0.01008733"/>
    <inertia ixx="0.00295838" ixy="-0.00001176" ixz="0.00006949" iyy="0.00355208"
             iyz="0.00004467" izz="0.00230558"/>
  </inertial>
  <visual>
    <geometry>
    <mesh filename="package://warehouse_simulation/urdf/meshes/LINK_15.stl"/>
    </geometry>
  </visual>
  </link>
  <gazebo reference="link_left_arm_1">
  </gazebo>

  <joint name="left_arm_1" type="fixed">
  <origin rpy="-0.349065850 0.0 0.0" xyz="0.0 0.0 0.0"/>
  <axis xyz="1 0 0"/>
  <parent link="link_left_arm_0"/>
  <child link="link_left_arm_1"/>
  <dynamics damping="50.0" friction="1.0"/>
  </joint>
  
  <link name="link_left_arm_2">
  <inertial>
    <mass value="0.0001"/>  
    <origin rpy="0 0 0" xyz="0.00066086 -0.00038583 -0.15742972"/>
    <inertia ixx="0.00842712" ixy="0.00000247" ixz="0.00036948" iyy="0.00802311"
             iyz="-0.00006550" izz="0.00295678"/>
  </inertial>
  <visual>
    <geometry>
    <mesh filename="package://warehouse_simulation/urdf/meshes/LINK_16.stl"/>
    </geometry>
  </visual>
  </link>
  <gazebo reference="link_left_arm_2">
  </gazebo>

  <joint name="left_arm_2" type="fixed">
  <origin rpy="0.0 0.0 0.0" xyz="0.0 0.0 0.0"/>
  <axis xyz="0 0 1"/>
  <parent link="link_left_arm_1"/>
  <child link="link_left_arm_2"/>
  <dynamics damping="50.0" friction="1.0"/>
  </joint>
  
  <link name="link_left_arm_3">
  <inertial>
    <mass value="0.0001"/>  
    <origin rpy="0 0 0" xyz="-0.01565298 0.00793126 -0.04997943"/>
    <inertia ixx="0.00756474" ixy="-0.00026771" ixz="-0.00155419" iyy="0.00772758"
             iyz="-0.00084364" izz="0.00199754"/>
  </inertial>
  <visual>
    <geometry>
    <mesh filename="package://warehouse_simulation/urdf/meshes/LINK_17.stl"/>
    </geometry>
  </visual>
  </link>
  <gazebo reference="link_left_arm_3">
  </gazebo>

  <joint name="left_arm_3" type="fixed">
  <origin rpy="0.0 0.0 0.0" xyz="0.031 0.0 -0.276"/>
  <axis xyz="0 1 0"/>
  <parent link="link_left_arm_2"/>
  <child link="link_left_arm_3"/>
  <dynamics damping="50.0" friction="1.0"/>
  </joint>
  
  <link name="link_left_arm_4">
  <inertial>
    <mass value="0.0001"/>  
    <origin rpy="0 0 0" xyz="0.00000011 0.02696036 0.06182110"/>
    <inertia ixx="0.00082466" ixy="0.0" ixz="0.0" iyy="0.00075398" 
             iyz="0.00025338" izz="0.00039794"/>
  </inertial>
  <visual>
    <geometry>
    <mesh filename="package://warehouse_simulation/urdf/meshes/LINK_18.stl"/>
    </geometry>
  </visual>
  </link>
  <gazebo reference="link_left_arm_4">
  </gazebo>

  <joint name="left_arm_4" type="fixed">
  <origin rpy="0.0 0.0 0.0" xyz="-0.031 0.0 -0.256"/>
  <axis xyz="0 0 1"/>
  <parent link="link_left_arm_3"/>
  <child link="link_left_arm_4"/>
  <dynamics damping="50.0" friction="1.0"/>
  </joint>
  
  <link name="link_left_arm_5">
  <inertial>
    <mass value="0.0001"/>  
    <origin rpy="0 0 0" xyz="0.00340082 0.00576824 -0.02507309"/>
    <inertia ixx="0.00233577" ixy="0.00003048" ixz="-0.00001191" iyy="0.00232580"
             iyz="-0.00019491" izz="0.00138375"/>
  </inertial>
  <visual>
    <geometry>
    <mesh filename="package://warehouse_simulation/urdf/meshes/LINK_19.stl"/>
    </geometry>
  </visual>
  </link>
  <gazebo reference="link_left_arm_5">
  </gazebo>

  <joint name="left_arm_5" type="fixed">
  <origin rpy="0.0 0.0 0.0" xyz="0.0 0.0 0.0"/>
  <axis xyz="0 1 0"/>
  <parent link="link_left_arm_4"/>
  <child link="link_left_arm_5"/>
  <dynamics damping="50.0" friction="1.0"/>
  </joint>
  
  <link name="link_left_arm_6">
  <inertial>
    <mass value="0.0001"/>  
    <origin rpy="0 0 0" xyz="-0.00066810 0.00031708 -0.09636043"/>
    <inertia ixx="0.00013511" ixy="-0.00000242" ixz="0.00000102" iyy="0.00014453"
             iyz="-0.00000094" izz="0.00025431"/>
  </inertial>
  <visual>
    <geometry>
    <mesh filename="package://warehouse_simulation/urdf/meshes/LINK_20.stl"/>
    </geometry>
  </visual>
  </link>
  <gazebo reference="link_left_arm_6">
  </gazebo>

  <joint name="left_arm_6" type="fixed">
  <origin rpy="0.0 0.0 0.0" xyz="0.0 0.0 0.0"/>
  <axis xyz="0 0 1"/>
  <parent link="link_left_arm_5"/>
  <child link="link_left_arm_6"/>
  <dynamics damping="50.0" friction="1.0"/>
  </joint>
  
  <link name="FT_sensor_R">
  <inertial>
    <mass value="0.0001"/>  
    <origin rpy="0 0 0" xyz="0.00010423 0.00108019 -0.01880676"/>
    <inertia ixx="0.00028587" ixy="-0.00000146" ixz="-0.00000026" iyy="0.00030459"
             iyz="-0.00000772" izz="0.00036377"/>
  </inertial>
  <visual>
    <geometry>
    <mesh filename="package://warehouse_simulation/urdf/meshes/FT_SENSOR_R.stl"/>
    </geometry>
  </visual>
  </link>
  <gazebo reference="FT_sensor_R">
  </gazebo>

  <joint name="tool_right" type="fixed">
  <origin rpy="0.0 0.0 0.0" xyz="0.0 0.0 -0.1087"/>
  <axis xyz="0 0 1"/>
  <parent link="link_right_arm_6"/>
  <child link="FT_sensor_R"/>
  </joint>
  
  <link name="FT_sensor_L">
  <inertial>
    <mass value="0.0001"/>  
    <origin rpy="0 0 0" xyz="-0.00010423 -0.00108019 -0.01880676"/>
    <inertia ixx="0.00028587" ixy="-0.00000146" ixz="0.00000026" iyy="0.00030459"
             iyz="0.00000772" izz="0.00036377"/>
  </inertial>
  <visual>
    <geometry>
    <mesh filename="package://warehouse_simulation/urdf/meshes/FT_SENSOR_L.stl"/>
    </geometry>
  </visual>
  </link>
  <gazebo reference="FT_sensor_L">
  </gazebo>

  <joint name="tool_left" type="fixed">
  <origin rpy="0.0 0.0 0" xyz="0.0 0.0 -0.1087"/>
  <axis xyz="0 0 1"/>
  <parent link="link_left_arm_6"/>
  <child link="FT_sensor_L"/>
  </joint>
  
  <link name="ee_right">
  <inertial>
    <mass value="0.0001"/>  
    <origin rpy="0 0 0" xyz="0.00212703 0.00000615 -0.04287176"/>
    <inertia ixx="0.00032067" ixy="0.00002383" ixz="-0.00000785" iyy="0.00059559"
             iyz="-0.00000007" izz="0.00052732"/>
  </inertial>
  <visual>
    <geometry>
    <mesh filename="package://warehouse_simulation/urdf/meshes/EE_BODY.stl"/>
    </geometry>
  </visual>
  </link>
  <gazebo reference="ee_right">
  </gazebo>

  <joint name="FT_Sensor_END_right" type="fixed">
  <origin rpy="0.0 0.0 0.0" xyz="0.0 0.0 -0.0461"/>
  <axis xyz="0 0 1"/>
  <parent link="FT_sensor_R"/>
  <child link="ee_right"/>
  </joint>
  
  <link name="ee_finger_r1">
  <inertial>
    <mass value="0.0001"/>  
    <origin rpy="0 0 0" xyz="0.00278346 -0.00000329 -0.02570112"/>
    <inertia ixx="0.00001231" ixy="0.0" ixz="-0.00000042" iyy="0.00001066" 
             iyz="0.0" izz="0.00000224"/>
  </inertial>
  <visual>
    <geometry>
    <mesh filename="package://warehouse_simulation/urdf/meshes/EE_FINGER.stl"/>
    </geometry>
  </visual>
  </link>
  <gazebo reference="ee_finger_r1">
  </gazebo>

  <joint name="gripper_finger_r1" type="prismatic" in_model_type="fixed">
  <origin rpy="0.0 0.0 0.0" xyz="0.003 0.0 -0.073"/>
  <axis xyz="-1 0 0"/>
  <parent link="ee_right"/>
  <child link="ee_finger_r1"/>
  <limit effort="1000" velocity="0.05" lower="-0.05" upper="0"/>
  </joint>
  
  <link name="ee_finger_r2">
  <inertial>
    <mass value="0.0001"/>  
    <origin rpy="0 0 0" xyz="0.00278346 -0.00000329 -0.02570112"/>
    <inertia ixx="0.00001231" ixy="0.0" ixz="-0.00000042" iyy="0.00001066" 
             iyz="0.0" izz="0.00000224"/>
  </inertial>
  <visual>
    <geometry>
    <mesh filename="package://warehouse_simulation/urdf/meshes/EE_FINGER.stl"/>
    </geometry>
  </visual>
  </link>
  <gazebo reference="ee_finger_r2">
  </gazebo>

  <joint name="gripper_finger_r2" type="prismatic" in_model_type="fixed">
  <origin rpy="0.0 0.0 3.1415926535" xyz="-0.003 0.0 -0.073"/>
  <axis xyz="1 0 0"/>
  <parent link="ee_right"/>
  <child link="ee_finger_r2"/>
  <limit effort="1000" velocity="0.05" lower="0" upper="0.05"/>
  </joint>
  
  <link name="ee_left">
  <inertial>
    <mass value="0.0001"/>  
    <origin rpy="0 0 0" xyz="0.00212703 0.00000615 -0.04287176"/>
    <inertia ixx="0.00032067" ixy="0.00002383" ixz="-0.00000785" iyy="0.00059559"
             iyz="-0.00000007" izz="0.00052732"/>
  </inertial>
  <visual>
    <geometry>
    <mesh filename="package://warehouse_simulation/urdf/meshes/EE_BODY.stl"/>
    </geometry>
  </visual>
  </link>
  <gazebo reference="ee_left">
  </gazebo>

  <joint name="FT_Sensor_END_left" type="fixed">
  <origin rpy="0.0 0.0 0.0" xyz="0.0 0.0 -0.0461"/>
  <axis xyz="0 0 1"/>
  <parent link="FT_sensor_L"/>
  <child link="ee_left"/>
  </joint>
  
  <link name="ee_finger_l1">
  <inertial>
    <mass value="0.0001"/>  
    <origin rpy="0 0 0" xyz="0.00278346 -0.00000329 -0.02570112"/>
    <inertia ixx="0.00001231" ixy="0.0" ixz="-0.00000042" iyy="0.00001066" 
             iyz="0.0" izz="0.00000224"/>
  </inertial>
  <visual>
    <geometry>
    <mesh filename="package://warehouse_simulation/urdf/meshes/EE_FINGER.stl"/>
    </geometry>
  </visual>
  </link>
  <gazebo reference="ee_finger_l1">
  </gazebo>

  <joint name="gripper_finger_l1" type="prismatic" in_model_type="fixed">
  <origin rpy="0.0 0.0 0.0" xyz="0.003 0.0 -0.073"/>
  <axis xyz="-1 0 0"/>
  <parent link="ee_left"/>
  <child link="ee_finger_l1"/>
  <limit effort="1000" velocity="0.05" lower="-0.05" upper="0"/>
  </joint>
  
  <link name="ee_finger_l2">
  <inertial>
    <mass value="0.0001"/>  
    <origin rpy="0 0 0" xyz="0.00278346 -0.00000329 -0.02570112"/>
    <inertia ixx="0.00001231" ixy="0.0" ixz="-0.00000042" iyy="0.00001066" 
             iyz="0.0" izz="0.00000224"/>
  </inertial>
  <visual>
    <geometry>
    <mesh filename="package://warehouse_simulation/urdf/meshes/EE_FINGER.stl"/>
    </geometry>
  </visual>
  </link>
  <gazebo reference="ee_finger_l2">
  </gazebo>

  <joint name="gripper_finger_l2" type="prismatic" in_model_type="fixed">
  <origin rpy="0.0 0.0 3.1415926535" xyz="-0.003 0.0 -0.073"/>
  <axis xyz="1 0 0"/>
  <parent link="ee_left"/>
  <child link="ee_finger_l2"/>
  <limit effort="1000" velocity="0.05" lower="0" upper="0.05"/>
  </joint>
  
  <link name="link_head_0">
  <inertial>
    <mass value="0.0001"/>  
    <origin rpy="0 0 0" xyz="-0.00800549 0.0 -0.01100308"/>
    <inertia ixx="0.00003307" ixy="0.0" ixz="-0.00000290" iyy="0.00002209" 
             iyz="0.0" izz="0.00003796"/>
  </inertial>
  <visual>
    <geometry>
    <mesh filename="package://warehouse_simulation/urdf/meshes/PAN_TILT_1.stl"/>
    </geometry>
  </visual>
  </link>
  <gazebo reference="link_head_0">
  </gazebo>

  <joint name="head_base" type="fixed">
  <origin rpy="0.0 0.0 0.0" xyz="0.022 0.0 0.120073451525"/>
  <axis xyz="0 0 1"/>
  <parent link="link_torso_5"/>
  <child link="link_head_0"/>
  </joint>
  
  <link name="link_head_1">
  <inertial>
    <mass value="0.0001"/>  
    <origin rpy="0 0 0" xyz="-0.01150679 -0.00114270 -0.00031579"/>
    <inertia ixx="0.00001850" ixy="-0.00000035" ixz="0.00000203" iyy="0.00002451"
             iyz="-0.00000010" izz="0.00002062"/>
  </inertial>
  <visual>
    <geometry>
    <mesh filename="package://warehouse_simulation/urdf/meshes/PAN_TILT_2.stl"/>
    </geometry>
  </visual>
  </link>
  <gazebo reference="link_head_1">
  </gazebo>

  <joint name="head_0" type="fixed">
  <origin rpy="0.0 0.0 0.0" xyz="0.0 0.0 0.02"/>
  <axis xyz="0 0 1"/>
  <parent link="link_head_0"/>
  <child link="link_head_1"/>
  <limit effort="1000" velocity="3.14" lower="-0.523" upper="0.523"/>
  </joint>
  
  <link name="link_head_2">
  <inertial>
    <mass value="0.0001"/>  
    <origin rpy="0 0 0" xyz="-0.00081966 0.00099024 0.02283704"/>
    <inertia ixx="0.00002046" ixy="0.00000001" ixz="-0.00000027" iyy="0.00001044"
             iyz="0.00000076" izz="0.00001291"/>
  </inertial>
  <visual>
    <geometry>
    <mesh filename="package://warehouse_simulation/urdf/meshes/PAN_TILT_3.stl"/>
    </geometry>
  </visual>
  </link>
  <gazebo reference="link_head_2">
  </gazebo>

  <joint name="head_1" type="fixed">
  <origin rpy="0.0 0.0 0.0" xyz="0.0 0.0 0.0"/>
  <axis xyz="0 1 0"/>
  <parent link="link_head_1"/>
  <child link="link_head_2"/>
  <limit effort="1000" velocity="3.14" lower="-0.35" upper="1.57"/>
  </joint>

  <!-- Swivel -->
  <link name="swivel">
  <inertial>
    <mass value="0.1"/> 
    <origin xyz="0 0 0"/>
    <inertia ixx="0.01" ixy="0" ixz="0"
         iyy="0.01" iyz="0" izz="0.01"/>
    </inertial>
  <visual>
    <origin xyz="0 0 0" rpy="0 0 0"/>
    <geometry name="pioneer_geom">
    <mesh filename="package://warehouse_simulation/meshes/swivel.stl"/>
    </geometry>
    <material name="swivel">
    <color rgba="0.5 0.5 0.5 1"/>
    </material>
  </visual>
  </link>
  <gazebo reference="swivel">
  <material value="Gazebo/Black"/>
  </gazebo>

  <joint name="base_swivel_joint" type="continuous">
  <origin xyz="-0.185 0 0.055" rpy="0 0 0"/>
  <axis xyz="0 0 1"/>
    <limit effort="100" velocity="100" k_velocity="0" />
    <joint_properties damping="0.0" friction="0.0" />
  <parent link="base_link"/>
  <child link="swivel"/>
  </joint>

  <!-- Center Wheel + Hubcap -->
  <link name="center_hubcap">
    <inertial>
    <mass value="0.01"/>  
    <origin xyz="0 0 0"/>
    <inertia ixx="0.012411765597" ixy="-0.000711733678" ixz="0.00050272983"
         iyy="0.015218160428" iyz="-0.000004273467" izz="0.011763977943"/>
    </inertial>
  <visual>
    <origin xyz="0 0 0" rpy="0 0 0"/>
    <geometry name="pioneer_geom">
    <mesh filename="package://warehouse_simulation/meshes/center_hubcap.stl"/>
    </geometry>
    <material name="swivel">
    <color rgba="0.5 0.5 0.5 1"/>
    </material>
  </visual>
  </link>
  <gazebo reference="center_hubcap">
  <material value="Gazebo/Black"/>
  </gazebo>

  <joint name="swivel_hubcap_joint" type="continuous">
  <origin xyz="-0.026 0 -0.016" rpy="0 0 0"/>
  <axis xyz="0 1 0"/>
  <anchor xyz="0 0 0"/>
    <limit effort="100" velocity="100" k_velocity="0" />
    <joint_properties damping="0.0" friction="0.0" />
  <parent link="swivel"/>
  <child link="center_wheel"/>
  </joint>

  <link name="center_wheel">
  <inertial>
    <mass value="0.1"/> 
    <origin xyz="0 0 0"/>
    <inertia ixx="0.012411765597" ixy="-0.000711733678" ixz="0.00050272983"
         iyy="0.015218160428" iyz="-0.000004273467" izz="0.011763977943"/>
    </inertial>
  <visual>
    <origin xyz="0 0 0" rpy="0 0 0"/>
    <geometry name="pioneer_geom">
    <mesh filename="package://warehouse_simulation/meshes/center_wheel.stl"/>
    </geometry>
    <material name="WheelBlack">
    <color rgba="0.117 0.117 0.117 1"/>
    </material>
  </visual>
  <collision>
    <origin xyz="0 0 0" rpy="${-3.1415927/2.0} 0 0"/>
    <geometry>
    <cylinder radius="0.0375" length="0.0314"/>
    </geometry>
  </collision>
  </link>
  <gazebo reference="center_wheel">
  <material value="Gazebo/Black"/>
  </gazebo>

  <joint name="center_wheel_joint" type="fixed">
  <origin xyz="-0.0035 0 -0.001" rpy="0 0 0"/>
  <parent link="center_wheel"/>
  <child link="center_hubcap"/>
  </joint>

  <xacro:p3dx_wheel suffix="left" parent="base_link" reflect="1"/>
  <xacro:p3dx_wheel suffix="right" parent="base_link" reflect="-1"/>

  <!-- Front + Back Sonar -->
  <link name="front_sonar">
  <inertial>
    <mass value="0.0001"/>  
    <origin xyz="0 0 0"/>
    <inertia ixx="1" ixy="0" ixz="0"
         iyy="1" iyz="0" izz="1"/>
  </inertial>
  <visual>
    <origin xyz="0 0 0" rpy="0 0 0"/>
    <geometry name="pioneer_geom">
    <mesh filename="package://warehouse_simulation/meshes/front_sonar.stl"/>
    </geometry>
    <material name="SonarYellow">
    <color rgba="0.715 0.583 0.210 1.0"/>
    </material>
  </visual>
  </link>
  <gazebo reference="front_sonar">
  <material value="Gazebo/Yellow"/>
  </gazebo>

  <joint name="base_front_joint" type="fixed">
  <origin xyz="-0.198 0 0.208" rpy="0 0 0"/>
  <parent link="base_link"/>
  <child link="front_sonar"/>
  </joint>

  <link name="back_sonar">
  <inertial>
    <mass value="0.0001"/>  
    <origin xyz="0 0 0"/>
    <inertia ixx="1" ixy="0" ixz="0"
         iyy="1" iyz="0" izz="1"/>
  </inertial>
  <visual>
    <origin xyz="0 0 0" rpy="0 0 0"/>
    <geometry name="pioneer_geom">
    <mesh filename="package://warehouse_simulation/meshes/back_sonar.stl"/>
    </geometry>
    <material name="SonarYellow">
    <color rgba="0.715 0.583 0.210 1.0"/>
    </material>
  </visual>
  </link>

  <gazebo reference="back_sonar">
  <material value="Gazebo/Yellow"/>
  </gazebo>

  <joint name="base_back_joint" type="fixed">
  <origin xyz="0.109 0 0.209" rpy="0 0 0"/>
  <!-- <origin xyz="0 0 0" rpy="0 0 0"/> -->
  <parent link="base_link"/>
  <child link="back_sonar"/>
  </joint>


  <!-- Imu -->
  <link name="imu_link"/>
  <joint name="base_to_imu" type="fixed">
    <axis rpy="0 0 0" xyz="0 0 0"/>
    <parent link="base_link"/>
    <child link="imu_link"/>
    <origin rpy="0 0 0" xyz="0 0 0.2"/>
  </joint>
  <gazebo reference="imu_link">
    <gravity>true</gravity>
    <sensor name="imu_sensor" type="imu">
      <always_on>true</always_on>
      <update_rate>10</update_rate>
      <visualize>true</visualize>
      <topic>imu</topic>
      <plugin filename="libgazebo_ros_imu_sensor.so" name="imu_plugin">
        <topicName>imu</topicName>
        <bodyName>imu_link</bodyName>
        <updateRateHZ>20.0</updateRateHZ>
        <gaussianNoise>0.0</gaussianNoise>
        <xyzOffset>0 0 0</xyzOffset>
        <rpyOffset>0 0 0</rpyOffset>
        <frameName>imu_link</frameName>
      </plugin>
      <pose>0 0 0 0 0 0</pose>
    </sensor>
  </gazebo>
 

 <!--_LIDAR -->
  <gazebo reference="laser">
    <material>Gazebo/FlatBlack</material>
    <sensor type="ray" name="lds_lfcd_sensor">
      <pose>0 0 0 0 0 0</pose>
      <visualize>false</visualize>
      <update_rate>5</update_rate>
      <ray>
        <scan>
          <horizontal>
            <samples>360</samples>
            <resolution>1</resolution>
            <min_angle>0.0</min_angle>
            <max_angle>6.28319</max_angle>
          </horizontal>
        </scan>
        <range>
          <min>0.120</min>
          <max>10.0</max>
          <resolution>0.050</resolution>
        </range>
        <noise>
          <type>gaussian</type>
          <mean>0.0</mean>
          <stddev>0.01</stddev>
        </noise>
      </ray>
      <plugin name="gazebo_ros_lds_lfcd_controller" filename="libgazebo_ros_laser.so">
        <topicName>scan</topicName>
        <frameName>laser</frameName>
      </plugin>
    </sensor>
  </gazebo>
 
  <joint name="scan_joint" type="fixed">
    <parent link="base_link"/>
    <child link="laser"/>
    <origin xyz="0 0 0.30" rpy="0 0 0"/>
  </joint>

  <link name="laser">
    <visual>
      <origin xyz="0 0 0.0" rpy="0 0 0"/>
      <geometry>
        <mesh filename="package://warehouse_simulation/meshes/lds.stl" scale="0.001 0.001 0.001"/>
      </geometry>
      <material name="dark"/>
    </visual>

    <collision>
      <origin xyz="0.015 0 -0.0065" rpy="0 0 0"/>
      <geometry>
        <cylinder length="0.0315" radius="0.055"/>
      </geometry>
    </collision>

    <inertial>
      <mass value="0.114" />
      <origin xyz="0 0 0" />
      <inertia ixx="0.001" ixy="0.0" ixz="0.0"
               iyy="0.001" iyz="0.0"
               izz="0.001" />
    </inertial>
  </link>


<!-- Robot locomotion plugin -->
  <gazebo>
    <plugin name="differential_drive_controller" filename="libgazebo_ros_diff_drive.so">
        <legacyMode>false</legacyMode>
        <alwaysOn>true</alwaysOn>
      <updateRate>100.0</updateRate>
      <leftJoint>base_left_wheel_joint</leftJoint>
        <rightJoint>base_right_wheel_joint</rightJoint>
      <wheelSeparation>0.32</wheelSeparation>
      <wheelDiameter>0.18</wheelDiameter>
      <wheelTorque>5</wheelTorque>
        <wheelAcceleration>0</wheelAcceleration>
        <robotNamespace>/</robotNamespace>
      <commandTopic>cmd_vel</commandTopic>
      <odometryTopic>odom</odometryTopic>
        <odometrySource>world</odometrySource><!--Other option is World or ENCODER-->
      <odometryFrame>odom</odometryFrame>
        <robotBaseFrame>base_link</robotBaseFrame>
        <publishTf>1</publishTf>
        <publishWheelTF>false</publishWheelTF>
        <publishOdomTF>true</publishOdomTF>
        <publishWheelJointState>false</publishWheelJointState>
        <rosDebugLevel>Warn</rosDebugLevel>
    </plugin>

    <!-- Fake localization plugin -->
    <plugin name="ground_truth_odometry" filename="libgazebo_ros_p3d.so">
      <alwaysOn>true</alwaysOn>
      <updateRate>100.0</updateRate>
      <bodyName>base_link</bodyName>
      <topicName>base_pose_ground_truth</topicName>
      <gaussianNoise>0.01</gaussianNoise>
      <frameName>map</frameName>-->
        <!-- initialize odometry for fake localization-->
      <xyzOffsets>0 0 0</xyzOffsets>
      <rpyOffsets>0 0 0</rpyOffsets>
    </plugin>

  </gazebo>

</robot>
